tests/actions.txt
O 10000 IBM B 10 100.0
O 10001 IBM B 10 99.0
O 10002 IBM S 5 101.0
O 10003 IBM S 5 100.0
O 10004 IBM S 5 100.0
X 10002
O 10005 IBM B 10 99.0
O 10006 IBM B 10 100.0
O 10007 IBM S 10 101.0
O 10008 IBM S 10 102.0
O 10009 IBM S 10 102.0
P
O 20000 IBM S 13 99.0
O 10010 IBM B 13 102.0

O 10011 TSLA B 13 102.0
O 10012 DOG B 13 102.0
O 10013 TWTR B 13 102.0
O 10014 BBY B 13 102.0
O 10015 AMZN B 13 102.0

